<?xml version="1.0" ?>
<!--
  Standalone URDF for Robot B - Universal Robots UR3
  Generated from config/ur3/{default_kinematics,visual_parameters,joint_limits}.yaml
  Meshes are referenced with paths relative to this file.
-->
<robot name="ur3_robot_b">

  <!-- ===== world link (fixed root) ===== -->
  <link name="world"/>

  <!-- ===== base_link (REP-103 aligned) ===== -->
  <link name="base_link"/>
  <joint name="base_joint" type="fixed">
    <parent link="world"/>
    <child link="base_link"/>
    <origin xyz="0 0 0" rpy="0 0 0"/>
  </joint>

  <!-- ===== base_link_inertia (rotated π around Z for controller alignment) ===== -->
  <link name="base_link_inertia">
    <visual>
      <origin xyz="0 0 0" rpy="0 0 3.14159265358979"/>
      <geometry>
        <mesh filename="meshes/ur3/visual/base.dae"/>
      </geometry>
    </visual>
    <collision>
      <origin xyz="0 0 0" rpy="0 0 3.14159265358979"/>
      <geometry>
        <mesh filename="meshes/ur3/collision/base.stl"/>
      </geometry>
    </collision>
  </link>
  <joint name="base_link-base_link_inertia" type="fixed">
    <parent link="base_link"/>
    <child link="base_link_inertia"/>
    <origin xyz="0 0 0" rpy="0 0 3.14159265358979"/>
  </joint>

  <!-- ===== shoulder_link ===== -->
  <link name="shoulder_link">
    <visual>
      <origin xyz="0 0 0" rpy="0 0 3.14159265358979"/>
      <geometry>
        <mesh filename="meshes/ur3/visual/shoulder.dae"/>
      </geometry>
    </visual>
    <collision>
      <origin xyz="0 0 0" rpy="0 0 3.14159265358979"/>
      <geometry>
        <mesh filename="meshes/ur3/collision/shoulder.stl"/>
      </geometry>
    </collision>
  </link>
  <joint name="shoulder_pan_joint" type="revolute">
    <parent link="base_link_inertia"/>
    <child link="shoulder_link"/>
    <origin xyz="0 0 0.1519" rpy="0 0 0"/>
    <axis xyz="0 0 1"/>
    <limit lower="-6.283185307" upper="6.283185307" effort="56.0" velocity="3.14159265358979"/>
  </joint>

  <!-- ===== upper_arm_link ===== -->
  <link name="upper_arm_link">
    <visual>
      <origin xyz="0 0 0.1198" rpy="1.5707963267949 0 -1.5707963267949"/>
      <geometry>
        <mesh filename="meshes/ur3/visual/upperarm.dae"/>
      </geometry>
    </visual>
    <collision>
      <origin xyz="0 0 0.1198" rpy="1.5707963267949 0 -1.5707963267949"/>
      <geometry>
        <mesh filename="meshes/ur3/collision/upperarm.stl"/>
      </geometry>
    </collision>
  </link>
  <joint name="shoulder_lift_joint" type="revolute">
    <parent link="shoulder_link"/>
    <child link="upper_arm_link"/>
    <origin xyz="0 0 0" rpy="1.570796327 0 0"/>
    <axis xyz="0 0 1"/>
    <limit lower="-6.283185307" upper="6.283185307" effort="56.0" velocity="3.14159265358979"/>
  </joint>

  <!-- ===== forearm_link ===== -->
  <link name="forearm_link">
    <visual>
      <origin xyz="0 0 0.0275" rpy="1.5707963267949 0 -1.5707963267949"/>
      <geometry>
        <mesh filename="meshes/ur3/visual/forearm.dae"/>
      </geometry>
    </visual>
    <collision>
      <origin xyz="0 0 0.0275" rpy="1.5707963267949 0 -1.5707963267949"/>
      <geometry>
        <mesh filename="meshes/ur3/collision/forearm.stl"/>
      </geometry>
    </collision>
  </link>
  <joint name="elbow_joint" type="revolute">
    <parent link="upper_arm_link"/>
    <child link="forearm_link"/>
    <origin xyz="-0.24365 0 0" rpy="0 0 0"/>
    <axis xyz="0 0 1"/>
    <limit lower="-3.14159265358979" upper="3.14159265358979" effort="28.0" velocity="3.14159265358979"/>
  </joint>

  <!-- ===== wrist_1_link ===== -->
  <link name="wrist_1_link">
    <visual>
      <origin xyz="0 0 -0.085" rpy="1.5707963267949 0 0"/>
      <geometry>
        <mesh filename="meshes/ur3/visual/wrist1.dae"/>
      </geometry>
    </visual>
    <collision>
      <origin xyz="0 0 -0.085" rpy="1.5707963267949 0 0"/>
      <geometry>
        <mesh filename="meshes/ur3/collision/wrist1.stl"/>
      </geometry>
    </collision>
  </link>
  <joint name="wrist_1_joint" type="revolute">
    <parent link="forearm_link"/>
    <child link="wrist_1_link"/>
    <origin xyz="-0.21325 0 0.11235" rpy="0 0 0"/>
    <axis xyz="0 0 1"/>
    <limit lower="-6.283185307" upper="6.283185307" effort="12.0" velocity="6.283185307"/>
  </joint>

  <!-- ===== wrist_2_link ===== -->
  <link name="wrist_2_link">
    <visual>
      <origin xyz="0 0 -0.083" rpy="0 0 0"/>
      <geometry>
        <mesh filename="meshes/ur3/visual/wrist2.dae"/>
      </geometry>
    </visual>
    <collision>
      <origin xyz="0 0 -0.083" rpy="0 0 0"/>
      <geometry>
        <mesh filename="meshes/ur3/collision/wrist2.stl"/>
      </geometry>
    </collision>
  </link>
  <joint name="wrist_2_joint" type="revolute">
    <parent link="wrist_1_link"/>
    <child link="wrist_2_link"/>
    <origin xyz="0 -0.08535 0" rpy="1.570796327 0 0"/>
    <axis xyz="0 0 1"/>
    <limit lower="-6.283185307" upper="6.283185307" effort="12.0" velocity="6.283185307"/>
  </joint>

  <!-- ===== wrist_3_link ===== -->
  <link name="wrist_3_link">
    <visual>
      <origin xyz="0 -0.00255 -0.082" rpy="1.5707963267949 0 0"/>
      <geometry>
        <mesh filename="meshes/ur3/visual/wrist3.dae"/>
      </geometry>
    </visual>
    <collision>
      <origin xyz="0 -0.00255 -0.082" rpy="1.5707963267949 0 0"/>
      <geometry>
        <mesh filename="meshes/ur3/collision/wrist3.stl"/>
      </geometry>
    </collision>
  </link>
  <joint name="wrist_3_joint" type="continuous">
    <parent link="wrist_2_link"/>
    <child link="wrist_3_link"/>
    <origin xyz="0 0.0819 0" rpy="1.570796326589793 3.141592653589793 3.141592653589793"/>
    <axis xyz="0 0 1"/>
    <limit effort="12.0" velocity="6.283185307"/>
  </joint>

  <!-- ===== auxiliary frames ===== -->
  <link name="ft_frame"/>
  <joint name="wrist_3_link-ft_frame" type="fixed">
    <parent link="wrist_3_link"/>
    <child link="ft_frame"/>
    <origin xyz="0 0 0" rpy="3.14159265358979 0 0"/>
  </joint>

  <link name="flange"/>
  <joint name="wrist_3-flange" type="fixed">
    <parent link="wrist_3_link"/>
    <child link="flange"/>
    <origin xyz="0 0 0" rpy="0 -1.5707963267949 -1.5707963267949"/>
  </joint>

  <link name="tool0"/>
  <joint name="flange-tool0" type="fixed">
    <parent link="flange"/>
    <child link="tool0"/>
    <origin xyz="0 0 0" rpy="1.5707963267949 0 1.5707963267949"/>
  </joint>

</robot>
